{
 "cells": [
  {
   "cell_type": "markdown",
   "metadata": {},
   "source": [
    "# 脱出構文と例外処理、大域脱出\n",
    "\n",
    "# 脱出構文、大域脱出\n",
    "\n",
    "* 処理を途中で抜ける方法\n",
    "    * return文\n",
    "    * ループを抜ける脱出構文\n",
    "    * メソッドを抜ける大域脱出"
   ]
  },
  {
   "cell_type": "markdown",
   "metadata": {},
   "source": [
    "## 脱出構文\n",
    "\n",
    "* break\n",
    "    * ループそのものを中断\n",
    "* next\n",
    "    * 中断して次に進む\n",
    "    * 他の言語ではcontinueに相当\n",
    "* redo\n",
    "    現在の処理をやり直す"
   ]
  },
  {
   "cell_type": "code",
   "execution_count": 2,
   "metadata": {
    "collapsed": false
   },
   "outputs": [
    {
     "name": "stdout",
     "output_type": "stream",
     "text": [
      "0\n",
      "1\n",
      "3\n",
      "4\n"
     ]
    },
    {
     "data": {
      "text/plain": [
       "5"
      ]
     },
     "execution_count": 2,
     "metadata": {},
     "output_type": "execute_result"
    }
   ],
   "source": [
    "5.times do |i|\n",
    "  next if i == 2\n",
    "  puts i\n",
    "end\n",
    "\n",
    "### 2を表示した後2を無限ループで表示\n",
    "# 5.times do |i|\n",
    "#   redo if i == 2\n",
    "#   puts i\n",
    "# end"
   ]
  },
  {
   "cell_type": "markdown",
   "metadata": {},
   "source": [
    "# 例外処理\n",
    "\n",
    "## rise\n",
    "\n",
    "* 例外を発生させる\n",
    "* 第一引数\n",
    "    * 例外クラス又はそのインスタンス\n",
    "* 第二引数\n",
    "    * メッセージ"
   ]
  },
  {
   "cell_type": "code",
   "execution_count": 4,
   "metadata": {
    "collapsed": false
   },
   "outputs": [
    {
     "ename": "ArgumentError",
     "evalue": "引数が不正です(例外クラス)",
     "output_type": "error",
     "traceback": [
      "\u001b[31mArgumentError\u001b[0m: 引数が不正です(例外クラス)",
      "\u001b[37m(pry):11:in `<main>'\u001b[0m",
      "\u001b[37m/Users/ftakao2007/work/jupyter/vendor/bundle/ruby/2.3.0/gems/pry-0.10.4/lib/pry/pry_instance.rb:355:in `eval'\u001b[0m",
      "\u001b[37m/Users/ftakao2007/work/jupyter/vendor/bundle/ruby/2.3.0/gems/pry-0.10.4/lib/pry/pry_instance.rb:355:in `evaluate_ruby'\u001b[0m",
      "\u001b[37m/Users/ftakao2007/work/jupyter/vendor/bundle/ruby/2.3.0/gems/pry-0.10.4/lib/pry/pry_instance.rb:323:in `handle_line'\u001b[0m",
      "\u001b[37m/Users/ftakao2007/work/jupyter/vendor/bundle/ruby/2.3.0/gems/pry-0.10.4/lib/pry/pry_instance.rb:243:in `block (2 levels) in eval'\u001b[0m",
      "\u001b[37m/Users/ftakao2007/work/jupyter/vendor/bundle/ruby/2.3.0/gems/pry-0.10.4/lib/pry/pry_instance.rb:242:in `catch'\u001b[0m",
      "\u001b[37m/Users/ftakao2007/work/jupyter/vendor/bundle/ruby/2.3.0/gems/pry-0.10.4/lib/pry/pry_instance.rb:242:in `block in eval'\u001b[0m",
      "\u001b[37m/Users/ftakao2007/work/jupyter/vendor/bundle/ruby/2.3.0/gems/pry-0.10.4/lib/pry/pry_instance.rb:241:in `catch'\u001b[0m",
      "\u001b[37m/Users/ftakao2007/work/jupyter/vendor/bundle/ruby/2.3.0/gems/pry-0.10.4/lib/pry/pry_instance.rb:241:in `eval'\u001b[0m",
      "\u001b[37m/Users/ftakao2007/work/jupyter/vendor/bundle/ruby/2.3.0/gems/iruby-0.3/lib/iruby/backend.rb:66:in `eval'\u001b[0m",
      "\u001b[37m/Users/ftakao2007/work/jupyter/vendor/bundle/ruby/2.3.0/gems/iruby-0.3/lib/iruby/backend.rb:12:in `eval'\u001b[0m",
      "\u001b[37m/Users/ftakao2007/work/jupyter/vendor/bundle/ruby/2.3.0/gems/iruby-0.3/lib/iruby/kernel.rb:87:in `execute_request'\u001b[0m",
      "\u001b[37m/Users/ftakao2007/work/jupyter/vendor/bundle/ruby/2.3.0/gems/iruby-0.3/lib/iruby/kernel.rb:47:in `dispatch'\u001b[0m",
      "\u001b[37m/Users/ftakao2007/work/jupyter/vendor/bundle/ruby/2.3.0/gems/iruby-0.3/lib/iruby/kernel.rb:37:in `run'\u001b[0m",
      "\u001b[37m/Users/ftakao2007/work/jupyter/vendor/bundle/ruby/2.3.0/gems/iruby-0.3/lib/iruby/command.rb:70:in `run_kernel'\u001b[0m",
      "\u001b[37m/Users/ftakao2007/work/jupyter/vendor/bundle/ruby/2.3.0/gems/iruby-0.3/lib/iruby/command.rb:34:in `run'\u001b[0m",
      "\u001b[37m/Users/ftakao2007/work/jupyter/vendor/bundle/ruby/2.3.0/gems/iruby-0.3/bin/iruby:5:in `<top (required)>'\u001b[0m",
      "\u001b[37m/Users/ftakao2007/work/jupyter/vendor/bundle/ruby/2.3.0/bin/iruby:23:in `load'\u001b[0m",
      "\u001b[37m/Users/ftakao2007/work/jupyter/vendor/bundle/ruby/2.3.0/bin/iruby:23:in `<main>'\u001b[0m"
     ]
    }
   ],
   "source": [
    "raise ArgumentError, \"引数が不正です(例外クラス)\""
   ]
  },
  {
   "cell_type": "code",
   "execution_count": 5,
   "metadata": {
    "collapsed": false
   },
   "outputs": [
    {
     "ename": "ArgumentError",
     "evalue": "引数が不正です(例外クラスのインスタンス)",
     "output_type": "error",
     "traceback": [
      "\u001b[31mArgumentError\u001b[0m: 引数が不正です(例外クラスのインスタンス)",
      "\u001b[37m(pry):12:in `<main>'\u001b[0m",
      "\u001b[37m/Users/ftakao2007/work/jupyter/vendor/bundle/ruby/2.3.0/gems/pry-0.10.4/lib/pry/pry_instance.rb:355:in `eval'\u001b[0m",
      "\u001b[37m/Users/ftakao2007/work/jupyter/vendor/bundle/ruby/2.3.0/gems/pry-0.10.4/lib/pry/pry_instance.rb:355:in `evaluate_ruby'\u001b[0m",
      "\u001b[37m/Users/ftakao2007/work/jupyter/vendor/bundle/ruby/2.3.0/gems/pry-0.10.4/lib/pry/pry_instance.rb:323:in `handle_line'\u001b[0m",
      "\u001b[37m/Users/ftakao2007/work/jupyter/vendor/bundle/ruby/2.3.0/gems/pry-0.10.4/lib/pry/pry_instance.rb:243:in `block (2 levels) in eval'\u001b[0m",
      "\u001b[37m/Users/ftakao2007/work/jupyter/vendor/bundle/ruby/2.3.0/gems/pry-0.10.4/lib/pry/pry_instance.rb:242:in `catch'\u001b[0m",
      "\u001b[37m/Users/ftakao2007/work/jupyter/vendor/bundle/ruby/2.3.0/gems/pry-0.10.4/lib/pry/pry_instance.rb:242:in `block in eval'\u001b[0m",
      "\u001b[37m/Users/ftakao2007/work/jupyter/vendor/bundle/ruby/2.3.0/gems/pry-0.10.4/lib/pry/pry_instance.rb:241:in `catch'\u001b[0m",
      "\u001b[37m/Users/ftakao2007/work/jupyter/vendor/bundle/ruby/2.3.0/gems/pry-0.10.4/lib/pry/pry_instance.rb:241:in `eval'\u001b[0m",
      "\u001b[37m/Users/ftakao2007/work/jupyter/vendor/bundle/ruby/2.3.0/gems/iruby-0.3/lib/iruby/backend.rb:66:in `eval'\u001b[0m",
      "\u001b[37m/Users/ftakao2007/work/jupyter/vendor/bundle/ruby/2.3.0/gems/iruby-0.3/lib/iruby/backend.rb:12:in `eval'\u001b[0m",
      "\u001b[37m/Users/ftakao2007/work/jupyter/vendor/bundle/ruby/2.3.0/gems/iruby-0.3/lib/iruby/kernel.rb:87:in `execute_request'\u001b[0m",
      "\u001b[37m/Users/ftakao2007/work/jupyter/vendor/bundle/ruby/2.3.0/gems/iruby-0.3/lib/iruby/kernel.rb:47:in `dispatch'\u001b[0m",
      "\u001b[37m/Users/ftakao2007/work/jupyter/vendor/bundle/ruby/2.3.0/gems/iruby-0.3/lib/iruby/kernel.rb:37:in `run'\u001b[0m",
      "\u001b[37m/Users/ftakao2007/work/jupyter/vendor/bundle/ruby/2.3.0/gems/iruby-0.3/lib/iruby/command.rb:70:in `run_kernel'\u001b[0m",
      "\u001b[37m/Users/ftakao2007/work/jupyter/vendor/bundle/ruby/2.3.0/gems/iruby-0.3/lib/iruby/command.rb:34:in `run'\u001b[0m",
      "\u001b[37m/Users/ftakao2007/work/jupyter/vendor/bundle/ruby/2.3.0/gems/iruby-0.3/bin/iruby:5:in `<top (required)>'\u001b[0m",
      "\u001b[37m/Users/ftakao2007/work/jupyter/vendor/bundle/ruby/2.3.0/bin/iruby:23:in `load'\u001b[0m",
      "\u001b[37m/Users/ftakao2007/work/jupyter/vendor/bundle/ruby/2.3.0/bin/iruby:23:in `<main>'\u001b[0m"
     ]
    }
   ],
   "source": [
    "raise ArgumentError.new, \"引数が不正です(例外クラスのインスタンス)\""
   ]
  },
  {
   "cell_type": "code",
   "execution_count": 10,
   "metadata": {
    "collapsed": false
   },
   "outputs": [
    {
     "ename": "ArgumentError",
     "evalue": "引数が不正です(メッセージを含む例外オブジェクト)",
     "output_type": "error",
     "traceback": [
      "\u001b[31mArgumentError\u001b[0m: 引数が不正です(メッセージを含む例外オブジェクト)",
      "\u001b[37m(pry):24:in `<main>'\u001b[0m",
      "\u001b[37m/Users/ftakao2007/work/jupyter/vendor/bundle/ruby/2.3.0/gems/pry-0.10.4/lib/pry/pry_instance.rb:355:in `eval'\u001b[0m",
      "\u001b[37m/Users/ftakao2007/work/jupyter/vendor/bundle/ruby/2.3.0/gems/pry-0.10.4/lib/pry/pry_instance.rb:355:in `evaluate_ruby'\u001b[0m",
      "\u001b[37m/Users/ftakao2007/work/jupyter/vendor/bundle/ruby/2.3.0/gems/pry-0.10.4/lib/pry/pry_instance.rb:323:in `handle_line'\u001b[0m",
      "\u001b[37m/Users/ftakao2007/work/jupyter/vendor/bundle/ruby/2.3.0/gems/pry-0.10.4/lib/pry/pry_instance.rb:243:in `block (2 levels) in eval'\u001b[0m",
      "\u001b[37m/Users/ftakao2007/work/jupyter/vendor/bundle/ruby/2.3.0/gems/pry-0.10.4/lib/pry/pry_instance.rb:242:in `catch'\u001b[0m",
      "\u001b[37m/Users/ftakao2007/work/jupyter/vendor/bundle/ruby/2.3.0/gems/pry-0.10.4/lib/pry/pry_instance.rb:242:in `block in eval'\u001b[0m",
      "\u001b[37m/Users/ftakao2007/work/jupyter/vendor/bundle/ruby/2.3.0/gems/pry-0.10.4/lib/pry/pry_instance.rb:241:in `catch'\u001b[0m",
      "\u001b[37m/Users/ftakao2007/work/jupyter/vendor/bundle/ruby/2.3.0/gems/pry-0.10.4/lib/pry/pry_instance.rb:241:in `eval'\u001b[0m",
      "\u001b[37m/Users/ftakao2007/work/jupyter/vendor/bundle/ruby/2.3.0/gems/iruby-0.3/lib/iruby/backend.rb:66:in `eval'\u001b[0m",
      "\u001b[37m/Users/ftakao2007/work/jupyter/vendor/bundle/ruby/2.3.0/gems/iruby-0.3/lib/iruby/backend.rb:12:in `eval'\u001b[0m",
      "\u001b[37m/Users/ftakao2007/work/jupyter/vendor/bundle/ruby/2.3.0/gems/iruby-0.3/lib/iruby/kernel.rb:87:in `execute_request'\u001b[0m",
      "\u001b[37m/Users/ftakao2007/work/jupyter/vendor/bundle/ruby/2.3.0/gems/iruby-0.3/lib/iruby/kernel.rb:47:in `dispatch'\u001b[0m",
      "\u001b[37m/Users/ftakao2007/work/jupyter/vendor/bundle/ruby/2.3.0/gems/iruby-0.3/lib/iruby/kernel.rb:37:in `run'\u001b[0m",
      "\u001b[37m/Users/ftakao2007/work/jupyter/vendor/bundle/ruby/2.3.0/gems/iruby-0.3/lib/iruby/command.rb:70:in `run_kernel'\u001b[0m",
      "\u001b[37m/Users/ftakao2007/work/jupyter/vendor/bundle/ruby/2.3.0/gems/iruby-0.3/lib/iruby/command.rb:34:in `run'\u001b[0m",
      "\u001b[37m/Users/ftakao2007/work/jupyter/vendor/bundle/ruby/2.3.0/gems/iruby-0.3/bin/iruby:5:in `<top (required)>'\u001b[0m",
      "\u001b[37m/Users/ftakao2007/work/jupyter/vendor/bundle/ruby/2.3.0/bin/iruby:23:in `load'\u001b[0m",
      "\u001b[37m/Users/ftakao2007/work/jupyter/vendor/bundle/ruby/2.3.0/bin/iruby:23:in `<main>'\u001b[0m"
     ]
    }
   ],
   "source": [
    "### 例外クラスのコンクラスタでメッセージを指定\n",
    "err = ArgumentError.new(\"引数が不正です(メッセージを含む例外オブジェクト)\")\n",
    "raise err"
   ]
  },
  {
   "cell_type": "code",
   "execution_count": 11,
   "metadata": {
    "collapsed": false
   },
   "outputs": [
    {
     "ename": "RuntimeError",
     "evalue": "例外クラスのインスタンスを省略した場合はRuntimeError",
     "output_type": "error",
     "traceback": [
      "\u001b[31mRuntimeError\u001b[0m: 例外クラスのインスタンスを省略した場合はRuntimeError",
      "\u001b[37m(pry):25:in `<main>'\u001b[0m",
      "\u001b[37m/Users/ftakao2007/work/jupyter/vendor/bundle/ruby/2.3.0/gems/pry-0.10.4/lib/pry/pry_instance.rb:355:in `eval'\u001b[0m",
      "\u001b[37m/Users/ftakao2007/work/jupyter/vendor/bundle/ruby/2.3.0/gems/pry-0.10.4/lib/pry/pry_instance.rb:355:in `evaluate_ruby'\u001b[0m",
      "\u001b[37m/Users/ftakao2007/work/jupyter/vendor/bundle/ruby/2.3.0/gems/pry-0.10.4/lib/pry/pry_instance.rb:323:in `handle_line'\u001b[0m",
      "\u001b[37m/Users/ftakao2007/work/jupyter/vendor/bundle/ruby/2.3.0/gems/pry-0.10.4/lib/pry/pry_instance.rb:243:in `block (2 levels) in eval'\u001b[0m",
      "\u001b[37m/Users/ftakao2007/work/jupyter/vendor/bundle/ruby/2.3.0/gems/pry-0.10.4/lib/pry/pry_instance.rb:242:in `catch'\u001b[0m",
      "\u001b[37m/Users/ftakao2007/work/jupyter/vendor/bundle/ruby/2.3.0/gems/pry-0.10.4/lib/pry/pry_instance.rb:242:in `block in eval'\u001b[0m",
      "\u001b[37m/Users/ftakao2007/work/jupyter/vendor/bundle/ruby/2.3.0/gems/pry-0.10.4/lib/pry/pry_instance.rb:241:in `catch'\u001b[0m",
      "\u001b[37m/Users/ftakao2007/work/jupyter/vendor/bundle/ruby/2.3.0/gems/pry-0.10.4/lib/pry/pry_instance.rb:241:in `eval'\u001b[0m",
      "\u001b[37m/Users/ftakao2007/work/jupyter/vendor/bundle/ruby/2.3.0/gems/iruby-0.3/lib/iruby/backend.rb:66:in `eval'\u001b[0m",
      "\u001b[37m/Users/ftakao2007/work/jupyter/vendor/bundle/ruby/2.3.0/gems/iruby-0.3/lib/iruby/backend.rb:12:in `eval'\u001b[0m",
      "\u001b[37m/Users/ftakao2007/work/jupyter/vendor/bundle/ruby/2.3.0/gems/iruby-0.3/lib/iruby/kernel.rb:87:in `execute_request'\u001b[0m",
      "\u001b[37m/Users/ftakao2007/work/jupyter/vendor/bundle/ruby/2.3.0/gems/iruby-0.3/lib/iruby/kernel.rb:47:in `dispatch'\u001b[0m",
      "\u001b[37m/Users/ftakao2007/work/jupyter/vendor/bundle/ruby/2.3.0/gems/iruby-0.3/lib/iruby/kernel.rb:37:in `run'\u001b[0m",
      "\u001b[37m/Users/ftakao2007/work/jupyter/vendor/bundle/ruby/2.3.0/gems/iruby-0.3/lib/iruby/command.rb:70:in `run_kernel'\u001b[0m",
      "\u001b[37m/Users/ftakao2007/work/jupyter/vendor/bundle/ruby/2.3.0/gems/iruby-0.3/lib/iruby/command.rb:34:in `run'\u001b[0m",
      "\u001b[37m/Users/ftakao2007/work/jupyter/vendor/bundle/ruby/2.3.0/gems/iruby-0.3/bin/iruby:5:in `<top (required)>'\u001b[0m",
      "\u001b[37m/Users/ftakao2007/work/jupyter/vendor/bundle/ruby/2.3.0/bin/iruby:23:in `load'\u001b[0m",
      "\u001b[37m/Users/ftakao2007/work/jupyter/vendor/bundle/ruby/2.3.0/bin/iruby:23:in `<main>'\u001b[0m"
     ]
    }
   ],
   "source": [
    "raise \"例外クラスのインスタンスを省略した場合はRuntimeError\""
   ]
  },
  {
   "cell_type": "markdown",
   "metadata": {},
   "source": [
    "## 例外が発生しても処理を続行させる\n",
    "\n",
    "* rescure節\n",
    "    * 例外が発生したときに実行される処理を記述\n",
    "* else節\n",
    "    * 例外が発生しなかった時の処理を記述\n",
    "* ensure節\n",
    "    * 例外の発生如何に関わらず実行される"
   ]
  },
  {
   "cell_type": "code",
   "execution_count": 19,
   "metadata": {
    "collapsed": false
   },
   "outputs": [
    {
     "name": "stdout",
     "output_type": "stream",
     "text": [
      "rescue節\n",
      "例外が発生すると実行されるrescue節\n",
      "else節\n",
      "例外は発生してない\n",
      "例外は発生していないので実行されるelse節\n",
      "ensure節\n",
      "例外が発生すると実行されるrescue節\n",
      "例外発生の如何に関わらず実行されるensure節\n"
     ]
    }
   ],
   "source": [
    "puts \"rescue節\"\n",
    "begin\n",
    "  1 / 0\n",
    "  puts \"例外の下の処理、実行されない\"\n",
    "rescue\n",
    "  puts \"例外が発生すると実行されるrescue節\"\n",
    "end\n",
    "\n",
    "puts \"else節\"\n",
    "begin\n",
    "  1\n",
    "  puts \"例外は発生してない\"\n",
    "rescue\n",
    "  puts \"例外は発生してないのでrescue節は実行されない\"\n",
    "else\n",
    "  puts \"例外は発生していないので実行されるelse節\"\n",
    "end\n",
    "\n",
    "puts \"ensure節\"\n",
    "begin\n",
    "  1 / 0\n",
    "  puts \"例外の下の処理、実行されない\"\n",
    "rescue\n",
    "  puts \"例外が発生すると実行されるrescue節\"\n",
    "else\n",
    "  puts \"例外が発生しているので実行されないelse節\"\n",
    "ensure\n",
    "  puts \"例外発生の如何に関わらず実行されるensure節\"\n",
    "end\n"
   ]
  },
  {
   "cell_type": "markdown",
   "metadata": {},
   "source": [
    "## rescue節はbeginを書かかずにrescue節"
   ]
  },
  {
   "cell_type": "code",
   "execution_count": 22,
   "metadata": {
    "collapsed": false
   },
   "outputs": [
    {
     "name": "stdout",
     "output_type": "stream",
     "text": [
      "begin無しrescue節\n"
     ]
    }
   ],
   "source": [
    "1 / 0 rescue puts \"begin無しrescue節\""
   ]
  },
  {
   "cell_type": "markdown",
   "metadata": {},
   "source": [
    "* メソッドの中でrescue節実行"
   ]
  },
  {
   "cell_type": "code",
   "execution_count": 23,
   "metadata": {
    "collapsed": false
   },
   "outputs": [
    {
     "name": "stdout",
     "output_type": "stream",
     "text": [
      "メソッドの中でrescueを実行\n"
     ]
    }
   ],
   "source": [
    "def foo\n",
    "  1 / 0\n",
    "rescue\n",
    "  puts \"メソッドの中でrescueを実行\"\n",
    "end\n",
    "foo"
   ]
  }
 ],
 "metadata": {
  "kernelspec": {
   "display_name": "Ruby 2.3.1",
   "language": "ruby",
   "name": "ruby"
  },
  "language_info": {
   "file_extension": ".rb",
   "mimetype": "application/x-ruby",
   "name": "ruby",
   "version": "2.3.1"
  }
 },
 "nbformat": 4,
 "nbformat_minor": 2
}
